<?xml version="1.0"?>

<robot name="mira">
    <material name="blue">
        <color rgba="0 0 0.8 1"/>
    </material>

    <material name="red">
        <color rgba="1 0 0 1"/>
    </material>

    <link name="base_link">
        <visual>
        <material name="blue" />
        <origin rpy="0 0 0" xyz="0 0 0"/>
        <geometry>
            <box size="0.1 0.1 0.2"/>
        </geometry>
        </visual>
    </link>
  
    <link name="roll_M1_link">
        <visual>
            <material name="red" />
            <origin rpy="0 0 0" xyz="0 0 0"/>
            <geometry>
                <cylinder radius="0.06" length="0.09"/>
            </geometry>
        </visual>
    </link>
    
    <joint name="roll_joint" type="continuous">
        <parent link="base_link"/>
        <child link="roll_M1_link"/>
        <origin xyz="0 0 0.145" rpy="0 0 0"/>
        <limit effort="0.1" velocity="0.005"/>
        <axis xyz="1 0 0"/>
    </joint>
  
</robot>