<?xml version="1.0" encoding="utf-8"?>
<!-- =================================================================================== -->
<!-- |    This document was autogenerated by xacro from xacro/gurdy.xacro              | -->
<!-- |    EDITING THIS FILE BY HAND IS NOT RECOMMENDED                                 | -->
<!-- =================================================================================== -->
<robot name="gurdy">
  <material name="orange">
    <color rgba="0.8 0.3 0 1"/>
  </material>
  <material name="grey">
    <color rgba="0.75 0.75 0.75 1"/>
  </material>
  <material name="red">
    <color rgba="0.6 0 0 1"/>
  </material>
  <material name="green">
    <color rgba="0 0.5 0 1"/>
  </material>
  <material name="blue">
    <color rgba="0 0 0.6 1"/>
  </material>
  <material name="yellow">
    <color rgba="1 1 0.4 1"/>
  </material>
  <link name="base_link">
    <collision>
      <origin rpy="0 0 0" xyz="0 0 0"/>
      <geometry>
        <box size="0.01 0.01 0.01"/>
      </geometry>
    </collision>
    <visual>
      <origin rpy="0 0 0" xyz="0 0 0"/>
      <geometry>
        <box size="0.01 0.01 0.01"/>
      </geometry>
      <material name="yellow"/>
    </visual>
  </link>
  <link name="head_link">
    <inertial>
      <origin rpy="0 0 0" xyz="0 0 0"/>
      <mass value="0.01"/>
      <inertia ixx="7.58333333333e-06" ixy="0" ixz="0" iyy="7.58333333333e-06" iyz="0" izz="1.25e-05"/>
    </inertial>
    <collision>
      <origin rpy="0 0 0" xyz="0 0 0"/>
      <geometry>
        <cylinder length="0.04" radius="0.05"/>
      </geometry>
    </collision>
    <visual>
      <origin rpy="0 0 0" xyz="0 0 0"/>
      <geometry>
        <mesh filename="package://my_gurdy_description/models/gurdy/meshes/gurdy_head_v2.dae"/>
      </geometry>
    </visual>
  </link>
  <link name="upperleg_M1_link">
    <inertial>
      <origin rpy="0 0 0" xyz="0 0 0"/>
      <mass value="0.01"/>
      <inertia ixx="3.015625e-06" ixy="0" ixz="0" iyy="3.015625e-06" iyz="0" izz="3.125e-08"/>
    </inertial>
    <collision>
      <origin rpy="0 0 0" xyz="0 0 0"/>
      <geometry>
        <cylinder length="0.06" radius="0.0025"/>
      </geometry>
    </collision>
    <visual>
      <origin rpy="0 0 0" xyz="0 0 0"/>
      <geometry>
        <mesh filename="package://my_gurdy_description/models/gurdy/meshes/gurdy_higherleg_v2.dae"/>
      </geometry>
    </visual>
  </link>
  <link name="upperleg_M2_link">
    <inertial>
      <origin rpy="0 0 0" xyz="0 0 0"/>
      <mass value="0.01"/>
      <inertia ixx="3.015625e-06" ixy="0" ixz="0" iyy="3.015625e-06" iyz="0" izz="3.125e-08"/>
    </inertial>
    <collision>
      <origin rpy="0 0 0" xyz="0 0 0"/>
      <geometry>
        <cylinder length="0.06" radius="0.0025"/>
      </geometry>
    </collision>
    <visual>
      <origin rpy="0 0 0" xyz="0 0 0"/>
      <geometry>
        <mesh filename="package://my_gurdy_description/models/gurdy/meshes/gurdy_higherleg_v2.dae"/>
      </geometry>
    </visual>
  </link>
  <link name="upperleg_M3_link">
    <inertial>
      <origin rpy="0 0 0" xyz="0 0 0"/>
      <mass value="0.01"/>
      <inertia ixx="3.015625e-06" ixy="0" ixz="0" iyy="3.015625e-06" iyz="0" izz="3.125e-08"/>
    </inertial>
    <collision>
      <origin rpy="0 0 0" xyz="0 0 0"/>
      <geometry>
        <cylinder length="0.06" radius="0.0025"/>
      </geometry>
    </collision>
    <visual>
      <origin rpy="0 0 0" xyz="0 0 0"/>
      <geometry>
        <mesh filename="package://my_gurdy_description/models/gurdy/meshes/gurdy_higherleg_v2.dae"/>
      </geometry>
    </visual>
  </link>
  <link name="lowerleg_M1_link">
    <inertial>
      <origin rpy="0 0 0" xyz="0 0 0"/>
      <mass value="0.01"/>
      <inertia ixx="3.005625e-06" ixy="0" ixz="0" iyy="3.005625e-06" iyz="0" izz="1.125e-08"/>
    </inertial>
    <collision>
      <origin rpy="0 0 0" xyz="0 0 0"/>
      <geometry>
        <cylinder length="0.06" radius="0.0015"/>
      </geometry>
    </collision>
    <visual>
      <origin rpy="0 0 0" xyz="0 0 0"/>
      <geometry>
        <mesh filename="package://my_gurdy_description/models/gurdy/meshes/gurdy_lowerleg_v2.dae"/>
      </geometry>
    </visual>
  </link>
  <link name="lowerleg_M2_link">
    <inertial>
      <origin rpy="0 0 0" xyz="0 0 0"/>
      <mass value="0.01"/>
      <inertia ixx="3.005625e-06" ixy="0" ixz="0" iyy="3.005625e-06" iyz="0" izz="1.125e-08"/>
    </inertial>
    <collision>
      <origin rpy="0 0 0" xyz="0 0 0"/>
      <geometry>
        <cylinder length="0.06" radius="0.0015"/>
      </geometry>
    </collision>
    <visual>
      <origin rpy="0 0 0" xyz="0 0 0"/>
      <geometry>
        <mesh filename="package://my_gurdy_description/models/gurdy/meshes/gurdy_lowerleg_v2.dae"/>
      </geometry>
    </visual>
  </link>
  <link name="lowerleg_M3_link">
    <inertial>
      <origin rpy="0 0 0" xyz="0 0 0"/>
      <mass value="0.01"/>
      <inertia ixx="3.005625e-06" ixy="0" ixz="0" iyy="3.005625e-06" iyz="0" izz="1.125e-08"/>
    </inertial>
    <collision>
      <origin rpy="0 0 0" xyz="0 0 0"/>
      <geometry>
        <cylinder length="0.06" radius="0.0015"/>
      </geometry>
    </collision>
    <visual>
      <origin rpy="0 0 0" xyz="0 0 0"/>
      <geometry>
        <mesh filename="package://my_gurdy_description/models/gurdy/meshes/gurdy_lowerleg_v2.dae"/>
      </geometry>
    </visual>
  </link>
  <link name="footM1_link">
    <inertial>
      <origin rpy="0 0 0" xyz="0 0 0"/>
      <mass value="0.02"/>
      <inertia ixx="5.12e-07" ixy="0" ixz="0" iyy="5.12e-07" iyz="0" izz="5.12e-07"/>
    </inertial>
    <collision>
      <origin rpy="0 0 0" xyz="0 0 0"/>
      <geometry>
        <sphere radius="0.008"/>
      </geometry>
    </collision>
    <visual>
      <origin rpy="0 0 0" xyz="0 0 0"/>
      <geometry>
        <sphere radius="0.008"/>
      </geometry>
      <material name="orange"/>
    </visual>
  </link>
  <link name="footM2_link">
    <inertial>
      <origin rpy="0 0 0" xyz="0 0 0"/>
      <mass value="0.02"/>
      <inertia ixx="5.12e-07" ixy="0" ixz="0" iyy="5.12e-07" iyz="0" izz="5.12e-07"/>
    </inertial>
    <collision>
      <origin rpy="0 0 0" xyz="0 0 0"/>
      <geometry>
        <sphere radius="0.008"/>
      </geometry>
    </collision>
    <visual>
      <origin rpy="0 0 0" xyz="0 0 0"/>
      <geometry>
        <sphere radius="0.008"/>
      </geometry>
      <material name="orange"/>
    </visual>
  </link>
  <link name="footM3_link">
    <inertial>
      <origin rpy="0 0 0" xyz="0 0 0"/>
      <mass value="0.02"/>
      <inertia ixx="5.12e-07" ixy="0" ixz="0" iyy="5.12e-07" iyz="0" izz="5.12e-07"/>
    </inertial>
    <collision>
      <origin rpy="0 0 0" xyz="0 0 0"/>
      <geometry>
        <sphere radius="0.008"/>
      </geometry>
    </collision>
    <visual>
      <origin rpy="0 0 0" xyz="0 0 0"/>
      <geometry>
        <sphere radius="0.008"/>
      </geometry>
      <material name="orange"/>
    </visual>
  </link>
  <joint name="fixed_joint" type="fixed">
    <parent link="base_link"/>
    <child link="head_link"/>
    <origin rpy="0 0 0" xyz="0 0 0"/>
  </joint>
  <joint name="head_upperlegM1_joint" type="revolute">
    <parent link="head_link"/>
    <child link="upperleg_M1_link"/>
    <origin rpy="3.14159 -1.05879e-22 0.523599" xyz="-0.02165 -0.0125 -0.008"/>
    <limit effort="0.1" lower="-1.5" upper="0" velocity="0.005"/>
    <axis xyz="0 1 0"/>
  </joint>
  <joint name="head_upperlegM2_joint" type="revolute">
    <parent link="head_link"/>
    <child link="upperleg_M2_link"/>
    <origin rpy="3.14159 0 2.61799" xyz="0.02165 -0.0125 -0.008"/>
    <limit effort="0.1" lower="-1.5" upper="0" velocity="0.005"/>
    <axis xyz="0 1 0"/>
  </joint>
  <joint name="head_upperlegM3_joint" type="revolute">
    <parent link="head_link"/>
    <child link="upperleg_M3_link"/>
    <origin rpy="3.14159 0 -1.5708" xyz="0 0.025 -0.008"/>
    <limit effort="0.1" lower="-1.5" upper="0" velocity="0.005"/>
    <axis xyz="0 1 0"/>
  </joint>
  <joint name="upperlegM1_lowerlegM1_joint" type="revolute">
    <parent link="upperleg_M1_link"/>
    <child link="lowerleg_M1_link"/>
    <origin rpy="0 0 3.14159" xyz="0 0.0095 0.06"/>
    <limit effort="0.1" lower="-2.9" upper="1.5708" velocity="0.005"/>
    <axis xyz="0 1 0"/>
  </joint>
  <joint name="upperlegM2_lowerlegM2_joint" type="revolute">
    <parent link="upperleg_M2_link"/>
    <child link="lowerleg_M2_link"/>
    <origin rpy="0 0 3.14159" xyz="0 0.0095 0.06"/>
    <limit effort="0.1" lower="-2.9" upper="1.5708" velocity="0.005"/>
    <axis xyz="0 1 0"/>
  </joint>
  <joint name="upperlegM3_lowerlegM3_joint" type="revolute">
    <parent link="upperleg_M3_link"/>
    <child link="lowerleg_M3_link"/>
    <origin rpy="0 0 -3.14159" xyz="0 0.0095 0.06"/>
    <limit effort="0.1" lower="-2.9" upper="1.5708" velocity="0.005"/>
    <axis xyz="0 1 0"/>
  </joint>
  <joint name="basefoot_peg_M1_joint_joint" type="fixed">
    <parent link="lowerleg_M1_link"/>
    <child link="footM1_link"/>
    <origin rpy="0 0 0" xyz="0 0 0.06"/>
  </joint>
  <joint name="basefoot_peg_M2_joint_joint" type="fixed">
    <parent link="lowerleg_M2_link"/>
    <child link="footM2_link"/>
    <origin rpy="0 0 0" xyz="0 0 0.06"/>
  </joint>
  <joint name="basefoot_peg_M3_joint_joint" type="fixed">
    <parent link="lowerleg_M3_link"/>
    <child link="footM3_link"/>
    <origin rpy="0 0 0" xyz="0 0 0.06"/>
  </joint>
  <gazebo>
    <plugin filename="libgazebo_ros_control.so" name="gazebo_ros_control">
      <robotNamespace>/gurdy</robotNamespace>
    </plugin>
  </gazebo>
  <gazebo>
    <plugin filename="libgazebo_ros_imu.so" name="gazebo_ros_imu_controller">
      <robotNamespace>/gurdy</robotNamespace>
      <topicName>imu/data</topicName>
      <serviceName>imu/service</serviceName>
      <bodyName>base_link</bodyName>
      <gaussianNoise>0</gaussianNoise>
      <rpyOffsets>0 0 0</rpyOffsets>
      <updateRate>10.0</updateRate>
      <alwaysOn>true</alwaysOn>
      <gaussianNoise>0</gaussianNoise>
    </plugin>
  </gazebo>
  <gazebo reference="base_link_link">
    <kp>1000.0</kp>
    <kd>1000.0</kd>
    <mu1>10.0</mu1>
    <mu2>10.0</mu2>
  </gazebo>
  <gazebo reference="upperleg_M1_link">
    <kp>1000.0</kp>
    <kd>1000.0</kd>
    <mu1>10.0</mu1>
    <mu2>10.0</mu2>
  </gazebo>
  <gazebo reference="upperleg_M2_link">
    <kp>1000.0</kp>
    <kd>1000.0</kd>
    <mu1>10.0</mu1>
    <mu2>10.0</mu2>
  </gazebo>
  <gazebo reference="upperleg_M3_link">
    <kp>1000.0</kp>
    <kd>1000.0</kd>
    <mu1>10.0</mu1>
    <mu2>10.0</mu2>
  </gazebo>
  <gazebo reference="lowerleg_M1_link">
    <kp>1000.0</kp>
    <kd>1000.0</kd>
    <mu1>10.0</mu1>
    <mu2>10.0</mu2>
  </gazebo>
  <gazebo reference="lowerleg_M2_link">
    <kp>1000.0</kp>
    <kd>1000.0</kd>
    <mu1>10.0</mu1>
    <mu2>10.0</mu2>
  </gazebo>
  <gazebo reference="lowerleg_M3_link">
    <kp>1000.0</kp>
    <kd>1000.0</kd>
    <mu1>10.0</mu1>
    <mu2>10.0</mu2>
  </gazebo>
  <transmission name="trans_upper1">
    <type>transmission_interface/SimpleTransmission</type>
    <joint name="head_upperlegM1_joint">
      <hardwareInterface>EffortJointInterface</hardwareInterface>
    </joint>
    <actuator name="head_upperlegM1_motor">
      <hardwareInterface>EffortJointInterface</hardwareInterface>
      <mechanicalReduction>1</mechanicalReduction>
    </actuator>
  </transmission>
  <transmission name="trans_upper2">
    <type>transmission_interface/SimpleTransmission</type>
    <joint name="head_upperlegM2_joint">
      <hardwareInterface>EffortJointInterface</hardwareInterface>
    </joint>
    <actuator name="head_upperlegM2_motor">
      <hardwareInterface>EffortJointInterface</hardwareInterface>
      <mechanicalReduction>1</mechanicalReduction>
    </actuator>
  </transmission>
  <transmission name="trans_upper3">
    <type>transmission_interface/SimpleTransmission</type>
    <joint name="head_upperlegM3_joint">
      <hardwareInterface>EffortJointInterface</hardwareInterface>
    </joint>
    <actuator name="head_upperlegM3_motor">
      <hardwareInterface>EffortJointInterface</hardwareInterface>
      <mechanicalReduction>1</mechanicalReduction>
    </actuator>
  </transmission>
  <transmission name="trans_lower1">
    <type>transmission_interface/SimpleTransmission</type>
    <joint name="upperlegM1_lowerlegM1_joint">
      <hardwareInterface>EffortJointInterface</hardwareInterface>
    </joint>
    <actuator name="upperlegM1_lowerlegM1_motor">
      <hardwareInterface>EffortJointInterface</hardwareInterface>
      <mechanicalReduction>1</mechanicalReduction>
    </actuator>
  </transmission>
  <transmission name="trans_lower2">
    <type>transmission_interface/SimpleTransmission</type>
    <joint name="upperlegM2_lowerlegM2_joint">
      <hardwareInterface>EffortJointInterface</hardwareInterface>
    </joint>
    <actuator name="upperlegM2_lowerlegM2_motor">
      <hardwareInterface>EffortJointInterface</hardwareInterface>
      <mechanicalReduction>1</mechanicalReduction>
    </actuator>
  </transmission>
  <transmission name="trans_lower3">
    <type>transmission_interface/SimpleTransmission</type>
    <joint name="upperlegM3_lowerlegM3_joint">
      <hardwareInterface>EffortJointInterface</hardwareInterface>
    </joint>
    <actuator name="upperlegM3_lowerlegM3_motor">
      <hardwareInterface>EffortJointInterface</hardwareInterface>
      <mechanicalReduction>1</mechanicalReduction>
    </actuator>
  </transmission>
</robot>

